<sdf version="1.6">
  <world name="world">
    <scene>
      <ambient>0.8 0.8 0.8 1.0</ambient>
      <background>0 0 0</background>
      <grid>false</grid>
    </scene>
    <include>
      <uri>model://sun</uri>
    </include>
    <gui>
      <camera name="gui_camera">
        <pose>20.479104662610585 -37.55747224880491 10 0 0.6 1.57</pose>
      </camera>
      <plugin name="toggle_floors" filename="libtoggle_floors.so">
        <floor name="B1" model_name="building_B1">
          <model name="LF001" />
          <model name="chart_cssd_door" />
        </floor>
      </plugin>
    </gui>
    <include>
      <name>mir100</name>
      <uri>model://MiR100</uri>
      <pose>18.01255272256649 -15.51754712329592 0.0 0 0 -1.5876168479207393</pose>
    </include>
    <model name="LF001">
      <pose>20.877901076436032 -21.57930857951358 0.0 0 0 -1.5685681746954838</pose>
      <link name="left">
        <pose>-0.3453687527803807 0 1.11 0 0 0</pose>
        <visual name="left_visual">
          <geometry>
            <box>
              <size>0.6807375055607614 0.03 2.2</size>
            </box>
          </geometry>
          <material>
            <ambient>120 60 0 0.6</ambient>
            <diffuse>120 60 0 0.6</diffuse>
          </material>
        </visual>
        <collision name="left_collision">
          <geometry>
            <box>
              <size>0.6807375055607614 0.03 2.2</size>
            </box>
          </geometry>
          <surface>
            <contact>
              <collide_bitmask>0x02</collide_bitmask>
            </contact>
          </surface>
        </collision>
        <inertial>
          <mass>50.0</mass>
          <inertia>
            <ixx>20.17041666666667</ixx>
            <iyy>22.0975147978212</iyy>
            <izz>1.9345981311545322</izz>
          </inertia>
        </inertial>
      </link>
      <joint name="left_joint" type="prismatic">
        <parent>world</parent>
        <child>left</child>
        <axis>
          <xyz>1 0 0</xyz>
          <limit>
            <lower>-0.6907375055607614</lower>
            <upper>0.0</upper>
            <effort>500.0</effort>
          </limit>
        </axis>
      </joint>
      <link name="right">
        <pose>0.3453687527803807 0 1.11 0 0 0</pose>
        <visual name="right_visual">
          <geometry>
            <box>
              <size>0.6807375055607614 0.03 2.2</size>
            </box>
          </geometry>
          <material>
            <ambient>120 60 0 0.6</ambient>
            <diffuse>120 60 0 0.6</diffuse>
          </material>
        </visual>
        <collision name="right_collision">
          <geometry>
            <box>
              <size>0.6807375055607614 0.03 2.2</size>
            </box>
          </geometry>
          <surface>
            <contact>
              <collide_bitmask>0x02</collide_bitmask>
            </contact>
          </surface>
        </collision>
        <inertial>
          <mass>50.0</mass>
          <inertia>
            <ixx>20.17041666666667</ixx>
            <iyy>22.0975147978212</iyy>
            <izz>1.9345981311545322</izz>
          </inertia>
        </inertial>
      </link>
      <joint name="right_joint" type="prismatic">
        <parent>world</parent>
        <child>right</child>
        <axis>
          <xyz>1 0 0</xyz>
          <limit>
            <lower>0.0</lower>
            <upper>0.6907375055607614</upper>
            <effort>500.0</effort>
          </limit>
        </axis>
      </joint>
      <plugin name="door" filename="libdoor.so">
        <v_max_door>0.2</v_max_door>
        <a_max_door>0.2</a_max_door>
        <a_nom_door>0.08</a_nom_door>
        <dx_min_door>0.001</dx_min_door>
        <f_max_door>100.0</f_max_door>
        <door name="LF001" type="DoubleSlidingDoor" left_joint_name="left_joint" right_joint_name="right_joint" />
      </plugin>
    </model>
    <model name="chart_cssd_door">
      <pose>11.403239579991617 -15.501177047558564 0.0 0 0 1.5707963267948966</pose>
      <link name="right">
        <pose>-0.48924521613185057 0 1.11 0 0 0</pose>
        <visual name="right_visual">
          <geometry>
            <box>
              <size>0.9684904322637011 0.03 2.2</size>
            </box>
          </geometry>
          <material>
            <ambient>120 60 0 0.6</ambient>
            <diffuse>120 60 0 0.6</diffuse>
          </material>
        </visual>
        <collision name="right_collision">
          <geometry>
            <box>
              <size>0.9684904322637011 0.03 2.2</size>
            </box>
          </geometry>
          <surface>
            <contact>
              <collide_bitmask>0x02</collide_bitmask>
            </contact>
          </surface>
        </collision>
        <inertial>
          <mass>50.0</mass>
          <inertia>
            <ixx>20.17041666666667</ixx>
            <iyy>24.074890489109713</iyy>
            <izz>3.9119738224430445</izz>
          </inertia>
        </inertial>
      </link>
      <joint name="right_joint" type="revolute">
        <parent>world</parent>
        <child>right</child>
        <axis>
          <xyz>0 0 1</xyz>
          <limit>
            <lower>0</lower>
            <upper>1.57</upper>
          </limit>
        </axis>
        <pose>-0.48924521613185057 0 0 0 0 0</pose>
      </joint>
      <link name="left">
        <pose>0.48924521613185057 0 1.11 0 0 0</pose>
        <visual name="left_visual">
          <geometry>
            <box>
              <size>0.9684904322637011 0.03 2.2</size>
            </box>
          </geometry>
          <material>
            <ambient>120 60 0 0.6</ambient>
            <diffuse>120 60 0 0.6</diffuse>
          </material>
        </visual>
        <collision name="left_collision">
          <geometry>
            <box>
              <size>0.9684904322637011 0.03 2.2</size>
            </box>
          </geometry>
          <surface>
            <contact>
              <collide_bitmask>0x02</collide_bitmask>
            </contact>
          </surface>
        </collision>
        <inertial>
          <mass>50.0</mass>
          <inertia>
            <ixx>20.17041666666667</ixx>
            <iyy>24.074890489109713</iyy>
            <izz>3.9119738224430445</izz>
          </inertia>
        </inertial>
      </link>
      <joint name="left_joint" type="revolute">
        <parent>world</parent>
        <child>left</child>
        <axis>
          <xyz>0 0 1</xyz>
          <limit>
            <lower>-1.57</lower>
            <upper>0</upper>
          </limit>
        </axis>
        <pose>0.48924521613185057 0 0 0 0 0</pose>
      </joint>
      <plugin name="door" filename="libdoor.so">
        <v_max_door>0.5</v_max_door>
        <a_max_door>0.3</a_max_door>
        <a_nom_door>0.15</a_nom_door>
        <dx_min_door>0.01</dx_min_door>
        <f_max_door>500.0</f_max_door>
        <door name="chart_cssd_door" type="DoubleSwingDoor" left_joint_name="left_joint" right_joint_name="right_joint" />
      </plugin>
    </model>
    <include>
      <name>building_B1</name>
      <uri>model://building_B1</uri>
      <pose>0 0 0.0 0 0 0</pose>
    </include>
  </world>
</sdf>
